I'm sorry, but an uncaught exception occurred.

While running game code:
  File "game/script.rpy", line 17, in script call
    call TiaDeCascais from _call_TiaDeCascais
  File "game/TiaDeCascais.rpy", line 3, in script
    if tia_points == 1:
  File "game/TiaDeCascais.rpy", line 3, in <module>
    if tia_points == 1:
NameError: name 'tia_points' is not defined

-- Full Traceback ------------------------------------------------------------

Full traceback:
  File "game/script.rpy", line 17, in script call
    call TiaDeCascais from _call_TiaDeCascais
  File "game/TiaDeCascais.rpy", line 3, in script
    if tia_points == 1:
  File "C:\Users\ASUS\Downloads\renpy-8.0.0-sdk\renpy\ast.py", line 2115, in execute
    if renpy.python.py_eval(condition):
  File "C:\Users\ASUS\Downloads\renpy-8.0.0-sdk\renpy\python.py", line 1092, in py_eval
    return py_eval_bytecode(code, globals, locals)
  File "C:\Users\ASUS\Downloads\renpy-8.0.0-sdk\renpy\python.py", line 1085, in py_eval_bytecode
    return eval(bytecode, globals, locals)
  File "game/TiaDeCascais.rpy", line 3, in <module>
    if tia_points == 1:
NameError: name 'tia_points' is not defined

Windows-10-10.0.22000 AMD64
Ren'Py 8.0.3.22090809
CozyJam 1.0
Sat Sep 17 18:45:29 2022
